{
 "cells": [
  {
   "cell_type": "code",
   "execution_count": 1,
   "id": "5348242e",
   "metadata": {},
   "outputs": [],
   "source": [
    "import boto3\n",
    "time.sleep(5)"
   ]
  },
  {
   "cell_type": "code",
   "execution_count": 6,
   "id": "a96751c9",
   "metadata": {},
   "outputs": [],
   "source": [
    "client = boto3.client(\n",
    "        'athena',\n",
    "        aws_access_key_id='ASIA4FG7EVU5S74FAGI3',\n",
    "        aws_secret_access_key='mAD6hS9/W1mbHsMmlEiYm9bzj5jStRI158jwDiiZ',\n",
    "        region_name ='ap-northeast-1',\n",
    "        aws_session_token=\"IQoJb3JpZ2luX2VjEOL//////////wEaCXVzLWVhc3QtMSJHMEUCIB9wwVrUfg64OWOrqRXFh2dDf6LkdEYobm6Q7fsuSsJ9AiEAhTzdxyGFDYzAoyfKnaveOvH7srD/NIOA2uZiNpPD7TYqkQMIKhACGgw4MzU4MzkxMTA0NTkiDKjgdzWKCeBCm/YWWyruAjPSGblTWNAOp3cdMzO8n7Rqz7DdgKyLfem6/Lp1MVzzweHykC0mVk3n39dRzlBkIIRLvuEMs5WIQmP2uX0j2NoC2q9Cbsb6nj/cZEh72kyN2pUwOYhUgCdDb3xg85qQV/VtI09iIszpOkLKKJD7uEW0wnesSgq+xFbBRR8d1aMODHRr8imTK/ueh5Hwb4dVg2EtCi0FTu/6q2jTv8XtxYKVDHSUmDBbYxvWZ1x7z71KvhcdHIwtjERwNbPifnBvMGu/0Jli9n6uNOW/6NhDWHTnVKGUtTqCbzakmlfBbhgeTVdfNAIli2H9A10KMDnUR+mYIjDuyduxW3JX1r+6OFmRwpWw8fIjoRhw4awzGnoseClEpeW7P4D8jNlZ1o9p7r6agY9dWmxTL7cOidawPgt2X541q93/JP6qiCAOT9nsX3IaW/XMQlbjUlNpoptjiPcdq6pYaiU4puR5YwOvhCYwecCoYlsxPxNwMscNdjDO7qqdBjqmASKaq1murRNJG6lauz9dq29dBaZHJTlJsG0y0Fx0ZeiLK2M65VnbFtAIcuRc4sqCYD4eJ6P27qTG4zw3epK3WLphm1xZRnXP2AvvrkYyv2ELnRhw/JBcFFJ7pX2VaFNfJSWKDGkaMQd+E6OzIVtH6eKM2XizYbG4W64HwIwCzSdIkBwJDnFsSbOKqmGTVzWA0+6ZZ1hZa5g5GRSVeA6G7mxgChTpNlw=\"\n",
    ")"
   ]
  },
  {
   "cell_type": "code",
   "execution_count": 7,
   "id": "918e0241",
   "metadata": {},
   "outputs": [
    {
     "ename": "InvalidRequestException",
     "evalue": "An error occurred (InvalidRequestException) when calling the StartQueryExecution operation: Only one sql statement is allowed. Got: CREATE DATABASE IF NOT EXISTS INCOME_GS_PRD; \n CREATE DATABASE IF NOT EXISTS dbo; \n CREATE DATABASE IF NOT EXISTS INCOME_PROD; \n CREATE DATABASE IF NOT EXISTS INCOME; \n ",
     "output_type": "error",
     "traceback": [
      "\u001b[0;31m---------------------------------------------------------------------------\u001b[0m",
      "\u001b[0;31mInvalidRequestException\u001b[0m                   Traceback (most recent call last)",
      "\u001b[0;32m/var/folders/mk/kz3q_4c11fl7hwzz26_7vx840000gp/T/ipykernel_12055/793428826.py\u001b[0m in \u001b[0;36m<module>\u001b[0;34m\u001b[0m\n\u001b[1;32m      1\u001b[0m \u001b[0;32mwith\u001b[0m \u001b[0mopen\u001b[0m\u001b[0;34m(\u001b[0m\u001b[0;34m\"source_database.ddl\"\u001b[0m\u001b[0;34m)\u001b[0m \u001b[0;32mas\u001b[0m \u001b[0mddl\u001b[0m\u001b[0;34m:\u001b[0m\u001b[0;34m\u001b[0m\u001b[0;34m\u001b[0m\u001b[0m\n\u001b[0;32m----> 2\u001b[0;31m     response = client.start_query_execution(\n\u001b[0m\u001b[1;32m      3\u001b[0m         \u001b[0mQueryString\u001b[0m\u001b[0;34m=\u001b[0m\u001b[0mddl\u001b[0m\u001b[0;34m.\u001b[0m\u001b[0mread\u001b[0m\u001b[0;34m(\u001b[0m\u001b[0;34m)\u001b[0m\u001b[0;34m,\u001b[0m\u001b[0;34m\u001b[0m\u001b[0;34m\u001b[0m\u001b[0m\n\u001b[1;32m      4\u001b[0m         \u001b[0mResultConfiguration\u001b[0m\u001b[0;34m=\u001b[0m\u001b[0;34m{\u001b[0m\u001b[0;34m\"OutputLocation\"\u001b[0m\u001b[0;34m:\u001b[0m \u001b[0;34m\"s3://ntuc-poc/querry/\"\u001b[0m\u001b[0;34m}\u001b[0m\u001b[0;34m\u001b[0m\u001b[0;34m\u001b[0m\u001b[0m\n\u001b[1;32m      5\u001b[0m     )\n",
      "\u001b[0;32m/opt/anaconda3/lib/python3.9/site-packages/botocore/client.py\u001b[0m in \u001b[0;36m_api_call\u001b[0;34m(self, *args, **kwargs)\u001b[0m\n\u001b[1;32m    506\u001b[0m                 )\n\u001b[1;32m    507\u001b[0m             \u001b[0;31m# The \"self\" in this scope is referring to the BaseClient.\u001b[0m\u001b[0;34m\u001b[0m\u001b[0;34m\u001b[0m\u001b[0m\n\u001b[0;32m--> 508\u001b[0;31m             \u001b[0;32mreturn\u001b[0m \u001b[0mself\u001b[0m\u001b[0;34m.\u001b[0m\u001b[0m_make_api_call\u001b[0m\u001b[0;34m(\u001b[0m\u001b[0moperation_name\u001b[0m\u001b[0;34m,\u001b[0m \u001b[0mkwargs\u001b[0m\u001b[0;34m)\u001b[0m\u001b[0;34m\u001b[0m\u001b[0;34m\u001b[0m\u001b[0m\n\u001b[0m\u001b[1;32m    509\u001b[0m \u001b[0;34m\u001b[0m\u001b[0m\n\u001b[1;32m    510\u001b[0m         \u001b[0m_api_call\u001b[0m\u001b[0;34m.\u001b[0m\u001b[0m__name__\u001b[0m \u001b[0;34m=\u001b[0m \u001b[0mstr\u001b[0m\u001b[0;34m(\u001b[0m\u001b[0mpy_operation_name\u001b[0m\u001b[0;34m)\u001b[0m\u001b[0;34m\u001b[0m\u001b[0;34m\u001b[0m\u001b[0m\n",
      "\u001b[0;32m/opt/anaconda3/lib/python3.9/site-packages/botocore/client.py\u001b[0m in \u001b[0;36m_make_api_call\u001b[0;34m(self, operation_name, api_params)\u001b[0m\n\u001b[1;32m    913\u001b[0m             \u001b[0merror_code\u001b[0m \u001b[0;34m=\u001b[0m \u001b[0mparsed_response\u001b[0m\u001b[0;34m.\u001b[0m\u001b[0mget\u001b[0m\u001b[0;34m(\u001b[0m\u001b[0;34m\"Error\"\u001b[0m\u001b[0;34m,\u001b[0m \u001b[0;34m{\u001b[0m\u001b[0;34m}\u001b[0m\u001b[0;34m)\u001b[0m\u001b[0;34m.\u001b[0m\u001b[0mget\u001b[0m\u001b[0;34m(\u001b[0m\u001b[0;34m\"Code\"\u001b[0m\u001b[0;34m)\u001b[0m\u001b[0;34m\u001b[0m\u001b[0;34m\u001b[0m\u001b[0m\n\u001b[1;32m    914\u001b[0m             \u001b[0merror_class\u001b[0m \u001b[0;34m=\u001b[0m \u001b[0mself\u001b[0m\u001b[0;34m.\u001b[0m\u001b[0mexceptions\u001b[0m\u001b[0;34m.\u001b[0m\u001b[0mfrom_code\u001b[0m\u001b[0;34m(\u001b[0m\u001b[0merror_code\u001b[0m\u001b[0;34m)\u001b[0m\u001b[0;34m\u001b[0m\u001b[0;34m\u001b[0m\u001b[0m\n\u001b[0;32m--> 915\u001b[0;31m             \u001b[0;32mraise\u001b[0m \u001b[0merror_class\u001b[0m\u001b[0;34m(\u001b[0m\u001b[0mparsed_response\u001b[0m\u001b[0;34m,\u001b[0m \u001b[0moperation_name\u001b[0m\u001b[0;34m)\u001b[0m\u001b[0;34m\u001b[0m\u001b[0;34m\u001b[0m\u001b[0m\n\u001b[0m\u001b[1;32m    916\u001b[0m         \u001b[0;32melse\u001b[0m\u001b[0;34m:\u001b[0m\u001b[0;34m\u001b[0m\u001b[0;34m\u001b[0m\u001b[0m\n\u001b[1;32m    917\u001b[0m             \u001b[0;32mreturn\u001b[0m \u001b[0mparsed_response\u001b[0m\u001b[0;34m\u001b[0m\u001b[0;34m\u001b[0m\u001b[0m\n",
      "\u001b[0;31mInvalidRequestException\u001b[0m: An error occurred (InvalidRequestException) when calling the StartQueryExecution operation: Only one sql statement is allowed. Got: CREATE DATABASE IF NOT EXISTS INCOME_GS_PRD; \n CREATE DATABASE IF NOT EXISTS dbo; \n CREATE DATABASE IF NOT EXISTS INCOME_PROD; \n CREATE DATABASE IF NOT EXISTS INCOME; \n "
     ]
    }
   ],
   "source": [
    "with open(\"source_database.ddl\") as ddl:\n",
    "    response = client.start_query_execution(\n",
    "        QueryString=ddl.read(),\n",
    "        ResultConfiguration={\"OutputLocation\": \"s3://ntuc-poc/querry/\"}\n",
    "    )\n",
    "    print(response[\"QueryExecutionId\"])\n"
   ]
  },
  {
   "cell_type": "code",
   "execution_count": null,
   "id": "e77e6ee7",
   "metadata": {},
   "outputs": [],
   "source": []
  }
 ],
 "metadata": {
  "kernelspec": {
   "display_name": "Python 3 (ipykernel)",
   "language": "python",
   "name": "python3"
  },
  "language_info": {
   "codemirror_mode": {
    "name": "ipython",
    "version": 3
   },
   "file_extension": ".py",
   "mimetype": "text/x-python",
   "name": "python",
   "nbconvert_exporter": "python",
   "pygments_lexer": "ipython3",
   "version": "3.9.13"
  }
 },
 "nbformat": 4,
 "nbformat_minor": 5
}
